<?xml version="1.0"?>
<robot xmlns:xacro="http://www.ros.org/wiki/xacro">

    <!-- Properties -->
    <xacro:include filename="$(find robot_description)/urdf/properties.urdf.xacro" />

    <!-- Components -->
    <xacro:include filename="$(find robot_description)/urdf/components/inertial_macros.xacro" />
    <xacro:include filename="$(find robot_description)/urdf/components/gazebo_materials.xacro" />
    <!-- <xacro:include filename="$(find robot_description)/urdf/components/gazebo_physics.xacro" /> -->

    <!-- Sensors -->
    <!-- <xacro:include filename="$(find robot_description)/sensors/generic_laser.urdf.xacro" />
    <xacro:include filename="$(find robot_description)/sensors/depth_sensor.urdf.xacro" /> -->
    <xacro:property name="M_PI" value="3.14159"/>
    <xacro:property name="scale_ratio" value="1" />
    <!-- Path Meshes -->
    <xacro:property name="path_meshes" value="file://$(find robot_description)/urdf/meshes" />

    <!-- ****************** Robot bases ***************************  -->
    <!-- Define the center of the main robot chassis projected on the ground -->
    <link name="base_footprint">
    </link>

    <!-- BASE LINK -->
    <link name="base_link">
        <visual>
            <origin xyz="0 0 0" rpy="0 0 0" />
            <!-- <geometry>
                <mesh scale="${scale_ratio} ${scale_ratio} ${scale_ratio}"
                    filename="${path_meshes}/base_link.stl" />
            </geometry> -->
            <geometry>
                <box size="0.5 0.345 0.377971" />
            </geometry>
            <material name="white">
            </material>
        </visual>
        <!-- <collision>
            <origin xyz="0.02 0 0.1" rpy="0 0 0" />
            <geometry>
                <box size="0.5 0.345 0.377971" />
            </geometry>
        </collision> -->
        <xacro:inertial_box mass="5.79174328389446" x="-0.0374777931065171"
            y="-0.000742607274570373" z="0.0517646177576365">
            <origin xyz="-0.0374777931065171 -0.000742607274570373 0.0517646177576365" rpy="0 0 0" />
        </xacro:inertial_box>
    </link>

    <joint name="base_to_footprint" type="fixed">
        <parent link="base_footprint" />
        <child link="base_link" />
        <origin xyz="0 0 1" rpy="0 0 0" />
    </joint>


    <!-- Right Wheel -->
    <link name="rightwheel_link">
        <visual>
            <origin xyz="0 0 0" rpy="0 0 0" />
            <!-- <geometry>
                <mesh scale="0.01 0.01 0.01"
                    filename="${path_meshes}/rightwheel1.stl" />
            </geometry> -->
            <geometry>
                <cylinder radius="0.082" length="0.06"/>
            </geometry>
            <material name="black">
            </material>
        </visual>
        <!-- <collision>
            <origin xyz="0 0.03 0" rpy="1.5708 0 0" />
            <geometry>
                <cylinder radius="0.082" length="0.06"/>
            </geometry>
        </collision> -->
        <xacro:inertial_box mass="1.0582" x="-1.2143E-17" y="0.033904" z="1.3878E-17">
            <origin xyz="-1.2143E-17 0.033904 1.3878E-17" rpy="0 0 0" />
        </xacro:inertial_box>
    </link>

    <!-- Right Wheel Joint -->
    <joint name="rightwheel_joint" type="continuous">
        <origin xyz="-0.12418 0.185 -0.063" rpy="-${M_PI/2} 0 0" />
        <parent link="base_link" />
        <child link="rightwheel_link" />
        <axis xyz="0 0 -1" />
    </joint>

    <!-- Left Wheel -->
    <link name="leftwheel_link">
        <visual>
            <origin xyz="0 0 0" rpy="0 0 0" />
            <!-- <geometry>
                <mesh scale="0.01 0.01 0.01"
                    filename="${path_meshes}/rightwheel1.stl" />
            </geometry> -->
            <geometry>
                <cylinder radius="0.082" length="0.06"/>
            </geometry>
            <material name="black">
            </material>
        </visual>
        <!-- <collision>
            <origin xyz="0 0.03 0" rpy="1.5708 0 0" />
            <geometry>
                <cylinder radius="0.082" length="0.06"/>
            </geometry>
        </collision> -->
        <xacro:inertial_box mass="1.0582" x="-2.4286E-17" y="-0.033904" z="4.1633E-17">
            <origin xyz="-2.4286E-17 -0.033904 4.1633E-17" rpy="0 0 0" />
        </xacro:inertial_box>
    </link>

    <!-- Left Wheel Joint -->
    <joint name="leftwheel_joint" type="continuous">
        <origin xyz="-0.12418 -0.185 -0.063" rpy="-${M_PI/2} 0 0" />
        <parent link="base_link" />
        <child link="leftwheel_link" />
        <axis xyz="0 0 1" />
    </joint>

    <!-- Caster Wheel -->
    <link name="casterwheel_link">
        <visual>
            <origin xyz="0 0 0" rpy="0 0 0" />
            <!-- <geometry>
                <mesh scale="${scale_ratio} ${scale_ratio} ${scale_ratio}"
                    filename="${path_meshes}/casterwheel.stl" />
            </geometry> -->
            <geometry>
                <cylinder radius="0.04" length="0.02"/>
            </geometry>
            <material name="blue">
            </material>
        </visual>
        <!-- <collision>
            <origin xyz="0 0 0" rpy="1.5708 0 0" />
            <geometry>
                <cylinder radius="0.04" length="0.02"/>
            </geometry>
        </collision> -->
        <xacro:inertial_box mass="0.10255" x="-0.0032546" y="0.0053327" z="0.013127">
            <origin xyz="-0.0032546 0.0053327 0.013127" rpy="0 0 0" />
        </xacro:inertial_box>
    </link>

    <!-- Caster Wheel Joint -->
    <joint name="casterwheel_joint" type="fixed">
        <origin xyz="0.25029 -0.01098 -0.1375" rpy="0 0 0" />
        <parent link="base_link" />
        <child link="casterwheel_link" />
        <axis xyz="0 0 0" />
    </joint>

    <!-- Lidar -->
    <!-- <link name="lidar_link">
        <visual>
            <origin xyz="0 0 0" rpy="0 0 0" />
            <geometry>
                <mesh scale="${scale_ratio} ${scale_ratio} ${scale_ratio}"
                    filename="${path_meshes}/lidar.STL" />
            </geometry>
            <material name="gray">
            </material>
        </visual>
        <collision>
            <origin xyz="0 0 0" rpy="0 0 0" />
            <geometry>
                <mesh scale="${scale_ratio} ${scale_ratio} ${scale_ratio}"
                    filename="${path_meshes}/lidar.STL" />
            </geometry>
        </collision>
        <xacro:inertial_box mass="0.2064" x="0.00050486" y="-3.7855E-05" z="-0.025753">
            <origin xyz="0.00050486 -3.7855E-05 -0.025753" rpy="0 0 0" />
        </xacro:inertial_box>
    </link> -->

    <!-- Lidar Joint -->
    <!-- <joint name="lidar_joint" type="fixed">
        <origin xyz="0.00082049 0.00875 0.12332" rpy="0 0 0" />
        <parent link="base_link" />
        <child link="lidar_link" />
        <axis xyz="0 0 1" />
    </joint> -->


    <!-- IMU -->
    <!-- <link name="imu_link">
        <visual>
            <origin xyz="0 0 0" rpy="0 0 0" />
            <geometry>
                <mesh scale="${scale_ratio} ${scale_ratio} ${scale_ratio}"
                    filename="${path_meshes}/imu.STL" />
            </geometry>
            <material name="black">
            </material>
        </visual>
        <collision>
            <origin xyz="0 0 0" rpy="0 0 0" />
            <geometry>
                <mesh scale="${scale_ratio} ${scale_ratio} ${scale_ratio}"
                    filename="${path_meshes}/imu.STL" />
            </geometry>
        </collision>
        <xacro:inertial_box mass="0.05157" x="-0.015015" y="-0.00012812" z="0.00021369">
            <origin xyz="-0.015015 -0.00012812 0.00021369" rpy="0 0 0" />
        </xacro:inertial_box>
    </link> -->

    <!-- IMU Joint -->
    <!-- <joint name="imu_joint" type="fixed">
        <origin xyz="0.05082 -0.0047896 0.053918" rpy="0 0 0" />
        <parent link="base_link" />
        <child link="imu_link" />
        <axis xyz="0 0 0" />
    </joint> -->

    <!-- Camera -->
    <!-- <link name="camerad435i_link">
        <visual>
            <origin xyz="0 0 0" rpy="0 0 0" />
            <geometry>
                <mesh scale="${scale_ratio} ${scale_ratio} ${scale_ratio}"
                    filename="${path_meshes}/camerad435i.STL" />
            </geometry>
            <material name="white">
            </material>
        </visual>
        <collision>
            <origin xyz="0 0 0" rpy="0 0 0" />
            <geometry>
                <mesh scale="${scale_ratio} ${scale_ratio} ${scale_ratio}"
                    filename="${path_meshes}/camerad435i.STL" />
            </geometry>
        </collision>
        <xacro:inertial_box mass="0.032264" x="0.0094812" y="3.7095E-05" z="-7.9734E-05">
            <origin xyz="0.0094812 3.7095E-05 -7.9734E-05" rpy="0 0 0" />
        </xacro:inertial_box>
    </link> -->

    <!-- Camera Joint -->
    <!-- <joint name="camerad435i_joint" type="fixed">
        <origin xyz="-0.20718 -0.08268 0.17016" rpy="0 0 0" />
        <parent link="base_link" />
        <child link="camerad435i_link" />
        <axis xyz="0 0 0" />
    </joint> -->

    <!-- Camera -->
    <!-- <link name="camerat265_link">
        <visual>
            <origin xyz="0 0 0" rpy="0 0 0" />
            <geometry>
                <mesh scale="${scale_ratio} ${scale_ratio} ${scale_ratio}"
                    filename="${path_meshes}/camerat265.STL" />
            </geometry>
            <material name="white">
            </material>
        </visual>
        <collision>
            <origin xyz="0 0 0" rpy="0 0 0" />
            <geometry>
                <mesh scale="${scale_ratio} ${scale_ratio} ${scale_ratio}"
                    filename="${path_meshes}/camerat265.STL" />
            </geometry>
        </collision>
        <xacro:inertial_box mass="0.030988" x="0.0061266" y="3.8568E-05" z="-1.9004E-05">
            <origin xyz="0.0061266 3.8568E-05 -1.9004E-05" rpy="0 0 0" />
        </xacro:inertial_box>
    </link> -->

    <!-- Camera Joint -->
    <!-- <joint name="camerat265_joint" type="fixed">
        <origin xyz="-0.20118 0.080908 0.16952" rpy="0 0 0" />
        <parent link="base_link" />
        <child link="camerat265_link" />
        <axis xyz="0 0 0" />
    </joint> -->

</robot>